Workbook

Sheet Base 3F
A1: F | B1: Cantidad de Empresas: --> | C1: =COUNTA(B5:B3164) -> 2175 | S1: =COUNTA(S5:S2041) -> 1875 | T1: =COUNTA(T5:T2041) -> 1640 | U1: =COUNTA(U5:U2041) -> 1481 | V1: =COUNTIFS(V5:V1956,"<>No encontrado / No tiene",V5:V1956,"<>") -> 984
A2: =COUNTIF(A5:A1968, "C") -> 1219 | B2: Contador de filas con info (C) -> tiene mail y tel - minimo 1 de c/u. | D2: Datos de la organización | O2: Datos de contacto
A3: =COUNTIF(A5:A1968, "F") -> 741 | B3: Contador de filas con falta de info (F) -> tiene mail o tel. | E3: Dirección | O3: Contacto 1 | Q3: Contacto 2 | S3: Datos generales | Z3: Observaciones / Comentario
B4: Razón Social AFIP | C4: CUIT AFIP | D4: Tipos de Organizacion | E4: Calle | F4: Número | G4: Localidad | H4: C.P. | I4: Cod. Actividad | J4: Rubro | K4: Actividad | L4: Tipo de Producto | M4: Productos Principales | N4: Cant. de empleados | O4: Nombre y apellido | P4: Celular | Q4: Nombre y apellido | R4: Celular | S4: Teléfono A | T4: Teléfono B | U4: Teléfono C | V4: Web / Instagram | W4: Importa | X4: Exporta | Y4: Activa
A5: C | B5: 1989 ESTUDIO A S.R.L. | ALEJANDRO Y MIGUEL ANGEL RIZZI S.H. | C5: 30709328995 | 30710682816 | D5: Empresa | E5: Cnel. Pringles | F5: 3552 | G5: Caseros | H5: 1678 | I5: 162909 | J5: Papel | K5: Fabricación de artículos de papel y cartón N.C.P. | L5: B2C | N5: 16 | O5: Angelina Muñoz | P5: 11 4424-3309 | S5: 11 4734-2356 | T5: 11 4716-1699 | V5: http://www.estudioapop.com.ar/ | W5: No | X5: No | Y5: Si
A6: C | B6: 2G ADHESIVOS S.R.L. | C6: 30714815179 | D6: Empresa | E6: Puan | F6: 4523 | G6: Caseros | H6: 1678 | I6: 202907 | J6: Química | K6: Fabricación de colas, adhesivos, aprestos y cementos excepto los odontológicos obtenidos de sustancias minerales y vegetales | N6: 0 | O6: Gabriel | P6: 15 5734-1450 | S6: 11 5734-1450 | T6: 11 4759-8416 | V6: https://www.dosg.com.ar/ | W6: No | X6: No | Y6: Si
A7: C | B7: A D S.A. | C7: 30710393725 | D7: Empresa | E7: Escultor Santiago Parodi | F7: 5028 | G7: Caseros | H7: 1678 | I7: 310020 | J7: Metalúrgica | K7: Fabricación de muebles y partes de muebles, excepto de madera | L7: B2B, B2C | M7: Muebles, exhibidores | N7: 22 | O7: Leandro Greco | S7: 11 4759-4142 | T7: 4115-4774 | V7: https://amasd.com.ar/ | W7: No | X7: No | Y7: Si
A8: C | B8: A PATKO Y CIA S.A. | C8: 30518263834 | D8: Empresa | E8: Trenque Lauquen | F8: 4749 | G8: Caseros | H8: 1678 | I8: 293090 | J8: Metalúrgica | K8: Fabricación de partes, piezas y accesorios para vehículos automotores y sus motores N.C.P. | N8: 4 | O8: Cristian Patko | S8: 11 4750-2658 | T8: 11 4750-5929 | V8: No encontrado / No tiene | W8: Si | X8: No | Y8: Si
A9: F | B9: A T G S.R.L. | C9: 30611422268 | D9: Empresa | E9: Av. Maipú | F9: 4381 | G9: Ciudadela | H9: 1702 | I9: 281102 | J9: Metalúrgica | K9: Fabricación de Estructuras Metálicas para la Construcción | L9: B2B | N9: 0 | S9: 4635-3692 | T9: 4488-1753 | V9: No encontrado / No tiene | W9: No | X9: No | Y9: Si
A10: F | B10: A V C S.R.L. | C10: 30662138157 | D10: Empresa | E10: Av. Rivadavia | F10: 12110 | G10: Ciudadela | H10: 1702 | I10: 801090 | J10: Servicios | K10: Servicios de seguridad e investigación N.C.P. | N10: 17 | S10: 4488-2330 | V10: No encontrado / No tiene | W10: No | X10: No | Y10: Si
A11: C | B11: A VALGO S.R.L. | C11: 30701156532 | D11: Empresa | E11: Gral. Roca | F11: 3397 | G11: Ciudadela | H11: 1704 | I11: 812090 | J11: Servicios | K11: Servicios de limpieza N.C.P. | N11: 11 | S11: 11 5307-2333 | T11: 4653-2507 | V11: https://valgo.com.ar/ | W11: No | X11: No | Y11: Si
A12: C | B12: AANTAJ S.R.L. | C12: 30709992178 | D12: Empresa | E12: Zapiola | F12: 21 | G12: Ciudadela | H12: 1702 | I12: 139209 | J12: Textil | K12: Fabricación de artículos confeccionados de materiales textiles N.C.P., excepto prendas de vestir | L12: B2B, B2C | N12: 4 | S12: 11 5290-7165 | T12: 4460-5957 | U12: 4650-2340 | V12: http://www.aantaj.com.ar/ | W12: Si | X12: Si | Y12: Si
A13: C | B13: ABAFLEX S.A. | C13: 30597429130 | D13: Empresa | E13: Chubut | F13: 4352 | G13: Ciudadela | H13: 1702 | I13: 222090 | J13: Plástica | K13: Fabricación de productos plásticos en formas básicas y artículos de plástico N.C.P., excepto muebles | L13: B2B | N13: 14 | S13: 4657-6800 | T13: 4657-4846 | V13: www.abaflex.com.ar | W13: Si | X13: Si | Y13: Si
A14: C | B14: ABASTECEDORA DEL OESTE S.R.L.E.F. | C14: 30647487285 | D14: Empresa | E14: Félix Ballester | F14: 262 | G14: Ciudadela | H14: 1702 | I14: 383961 | J14: Electrónica | K14: Fabricación de aparatos y suministros eléctricos no clasificados en otra parte | N14: 0 | S14: 4653 5026 | T14: 4657 0355 | V14: No encontrado / No tiene | W14: No | X14: No | Y14: Si
A15: C | B15: ABBOMAR S.A. | C15: 30710802552 | D15: Empresa | E15: Raúl Scalabrini Ortiz | F15: 2945 | G15: Caseros | H15: 1678 | I15: 433010 | J15: Construcción | K15: Instalaciones de carpintería, herrería de obra y artística (Incluye instalación de puertas y ventanas, carpintería metálica y no metálica, etc.) | L15: B2C | N15: 6 | S15: 15 5101-3019 | T15: 4843-9243 | U15: 11 5101-3019 | V15: http://www.abbomar.com/contacto | W15: No | X15: No | Y15: Si
A16: C | B16: ABELARDO ESTEBAN (VALVULAS ESTEBAN) | C16: 20105339330 | D16: Persona Física | E16: Constancia | F16: 1130 | G16: Ciudadela | H16: 1702 | I16: 259993 | J16: Metalúrgica | K16: Fabricación de productos metálicos de tornería y/o matricería | O16: Lilia Pardo? (Gestora?) | S16: 4653-0950 | T16: 4657-8146 | V16: https://valvulas-esteban.com.ar/
A17: C | B17: ABERMATIC S.R.L. | C17: 30707243844 | D17: Empresa | E17: Santiago Bonifacini | F17: 5337 | G17: Caseros | H17: 1678 | I17: 271010 | J17: Metalúrgica | K17: Fabricación de motores, generadores y transformadores eléctricos | L17: B2B, BK | N17: 30 | O17: Sandro Vivaldi (Socio gerente) | S17: 4750-5309 | T17: 4750-3952 | U17: 4750-3233 | V17: www.abermatic.com | W17: Si | X17: Si | Y17: Si
A18: F | B18: ABIS S.R.L. | C18: 30663783013 | D18: Empresa | E18: Marco Polo | F18: 5157 | G18: Villa Bosch | H18: 1682 | I18: 452900 | J18: Construcción | K18: Obras de ingeniería civil N.C.P. | L18: B2B | N18: 0 | S18: 4743-7245 | V18: No encontrado / No tiene | W18: No | X18: No | Y18: Si
A19: C | B19: ABK SOCIEDAD DE RESPONSABILIDAD LIMITADA | C19: 33625752499 | D19: Empresa | E19: Dr. José Rebizzo | F19: 5683 | G19: Caseros | H19: 1678 | I19: 202907 | J19: Química | K19: Fabricación de colas, adhesivos, aprestos y cementos excepto los odontológicos obtenidos de sustancias minerales y vegetales | N19: 10 | P19: 11 4750-2910 | S19: 11 3518-7549 | T19: 11 4750-2910 | U19: 4734-2170 | V19: https://www.abk.com.ar/ | W19: Si | X19: Si | Y19: Si
A20: F | B20: ACABADOS NEWTON S.R.L. | C20: 30714258377 | D20: Empresa | E20: General Villegas | F20: 5236 | G20: Caseros | H20: 1678 | I20: 329090 | J20: Metalúrgica | K20: Tratamiento y acabado de superficies como herrajes para muebles y obra, ferretería, cortinería, burlonería, bisagras, etc | N20: 4 | S20: 4115-7357/57 | T20: 4658-7386 | V20: http://www.acabadosnewton.com.ar/ | W20: No | X20: No | Y20: Si
A21: C | B21: ACCECUER S.A. | C21: 30632566448 | D21: Empresa | E21: Juan Zanella | F21: 4656 | G21: Caseros | H21: 1678 | I21: 151200 | J21: Cuero | K21: Fabricación de maletas, bolsos de mano y similares, artículos de talabartería y artículos de cuero N.C.P. | L21: B2B, B2C | M21: Manufactura de cinturones de cuero y artículos de marroquinería | N21: 23 | S21: 11 2280 1856 | T21: 5293-0118 | U21: 4541-3222 | V21: http://www.accecuer.com.ar/ | W21: Si | X21: Si | Y21: Si
A22: C | B22: ACEROS ACEPER DE DALL ASTA CLAUDIA VIVIANA | C22: 27162030618 | D22: Persona Física | E22: Esteban Merlo | F22: 4369 | G22: Caseros | H22: 1678 | I22: 475290 | J22: Construcción | K22: Venta al por menor de materiales de construcción | S22: 4115-6713 | T22: 4750-6996 | U22: 1140376715 | V22: http://acerosaceper.com.ar/
A23: C | B23: ACEROS COFER S.A. | C23: 30707576444 | D23: Empresa | E23: Av. Pres. Juan Domingo Perón | F23: 8299 | G23: Pablo Podestá | H23: 1657 | I23: 259999 | J23: Metalúrgica | K23: Fabricación de productos elaborados de metal N.C.P. | L23: B2B | N23: 31 | O23: Juan Carlos Luna | Q23: Fabian Fernandez Crasso | R23: 15 3210-1300 | 15 7163-0905 | S23: 4848-1010 | 4848-4140 | T23: 4848-3300 | U23: 4848-1600 | V23: https://www.aceroscofer.com.ar/ | W23: Si | X23: Si | Y23: Si
A24: C | B24: ACEROS DR SOC. ANONIMA | C24: 30711724997 | D24: Empresa | E24: Teodoro Plaza | F24: 3237 | G24: Ciudadela | H24: 1702 | I24: 259999 | J24: Metalúrgica | K24: Fabricación de productos elaborados de metal N.C.P. | S24: 4653-3183 | V24: http://acerosdr.com.ar/contacto.html
A25: C | B25: ACEROS INOXIDABLES ALVEAR S.R.L. | C25: 33715692649 | D25: Empresa | E25: Av. Marcelo T. de Alvear | F25: 2554 | G25: José Ingenieros | H25: 1703 | I25: 243100 | J25: Metalúrgica | K25: Cortes y plegados trabajos especiales en acero inoxidable para la industria gastronomica, farmaceutica, y de arquitectura | O25: Roberto | P25: 11 5569-2593 | S25: 4712-9130 | V25: No encontrado / No tiene
A26: C | B26: ACEROS INOXIDABLES CASEROS S.R.L. | C26: 30708161272 | D26: Empresa | E26: Av. Bartolomé Mitre | F26: 3244 | G26: Caseros | H26: 1678 | I26: 259999 | J26: Metalúrgica | K26: Fabricación de productos elaborados de metal N.C.P. | L26: B2B | N26: 26 | O26: Graciela Estente | P26: 11 6700-3265 | 11 4033-6448 | S26: 4734-1816 | T26: 4734-1613 | U26: 4750-5137 | 11 5322-8121 | V26: http://www.acerosinoxidablescaseros.com/ | W26: No | X26: No | Y26: Si
A27: C | B27: ACEROS MB S.A. | C27: 30584398694 | D27: Empresa | E27: General Villegas | F27: 4353 | G27: Caseros | H27: 1678 | I27: 241009 | J27: Metalúrgica | K27: Fabricación de industrias básicas de productos de hierro y acero N.C.P. (incluye la producción de hojalata) | N27: 62 | O27: Víctor M. Holub (Dir.) | P27: 11 4936-5726 | Q27: Juan Pablo Montan | R27: 11 3165-2541 | S27: 4759-1211 | 4936-5726 | T27: 4759-1092 | U27: 4750-9177 | V27: https://www.acerosmb.com.ar/ | W27: Si | X27: Si | Y27: Si
A28: F | B28: ACERPEL S.R.L. | C28: 30687238881 | D28: Empresa | E28: Ntra. Sra. de la Merced | F28: 3979 | G28: Caseros | H28: 1678 | I28: 282901 | J28: Metalúrgica | K28: Fabricación de maquinaria para la industria del papel y las artes gráficas | L28: B2B, BK | N28: 0 | S28: 4759-4802 | V28: No encontrado / No tiene | W28: No | X28: No | Y28: Si
A29: C | B29: ACHILLI VIVIANA Y ACHILLI DIEGO SOC. H. (HELADOS LOS AMORES) | C29: 33708320159 | D29: Empresa | E29: Martin Fierro | F29: 7853 | G29: Villa Bosch | H29: 1682 | I29: 105030 | J29: Alimenticia | K29: Elaboración industrial de helados | N29: 47 | O29: Diego Achilli (Concejal) | P29: 11 4992-6173 | S29: 11 5308-1563 | V29: https://los-amores.com.ar/ | W29: Si | X29: Si | Y29: Si
A30: C | B30: ACICA S.R.L. | C30: 30620246596 | D30: Empresa | E30: Av. Marcelo T. de Alvear | F30: 4492 | G30: Ciudadela | H30: 1702 | I30: 293099 | J30: Electrónica | K30: Fabricación de Aparatos y Accesorios Eléctricos N.C.P. | N30: 0 | S30: 11 4488-1599 | V30: No encontrado / No tiene | W30: Si | X30: Si | Y30: No
A31: C | B31: ACLAUJOR S.R.L. | C31: 30710864612 | D31: Empresa | E31: José Ignacio Rucci | F31: 65 | G31: Ciudadela | H31: 1702 | I31: 222109 | J31: Servicios | K31: Impresion excepto de diarios y revistas | N31: 0 | S31: 11 4657-2370 | V31: No encontrado / No tiene | W31: No | X31: No | Y31: Si
A32: F | B32: ACQUAIDEAS S.R.L. | C32: 30710015615 | D32: Empresa | E32: Agustín Cafferata | F32: 5196 | G32: Caseros | H32: 1678 | I32: 241009 | J32: Metalúrgica | K32: Fabricación en Industrias básicas de productos de Hierro y Acero N.C.P. | N32: 0 | S32: 4716-9334 | V32: No encontrado / No tiene | W32: No | X32: No | Y32: Si
A33: F | B33: ACQUAVAL S.R.L. | C33: 30637276499 | D33: Empresa | E33: Guaminí | F33: 5444 | G33: Caseros | H33: 1678 | I33: 289993 | J33: Metalúrgica | K33: Fabricación de productos metálicos de tornería y/o matricería | L33: B2B | N33: 0 | S33: 11 4734-6514 | V33: No encontrado / No tiene | W33: No | X33: No | Y33: Si
A34: C | B34: ACRILICOS AMENDOLA MARIANI S.R.L. | C34: 30647516366 | D34: Empresa | E34: Av. San Martín | F34: 1727 | G34: Caseros | H34: 1678 | I34: 222090 | J34: Plástica | K34: Fabricación de productos plásticos en formas básicas y artículos de plástico N.C.P., excepto muebles | L34: B2B | N34: 2 | O34: Carlos Améndola | P34: 11 4086-0033 | Q34: Oscar Jorge Mariani | R34: 15 4086-0033 | S34: 4512-7584 | T34: 4512-7583 | U34: 4512-7582 | V34: https://www.instagram.com/acrilicosamendola/?hl=es-la | W34: Si | X34: Si | Y34: Si
A35: F | B35: ACRILICOS DINAMICA S.R.L. | C35: 30586071099 | D35: Empresa | E35: Pueyrredón | F35: 3564 | G35: Ciudadela | H35: 1702 | I35: 390968 | J35: Metalúrgica | K35: Fabricación y armado letreros anuncios | N35: 0 | V35: No encontrado / No tiene | W35: No | X35: No | Y35: Si
A36: C | B36: ACRILICOS MAJO S.A. | C36: 30663738700 | D36: Empresa | E36: Av. Gaona | F36: 4019 | G36: Ciudadela | H36: 1702 | I36: 252090 | J36: Plástica | K36: Fabricación de productos plásticos en formas básicas y artículos de plástico N.C.P., excepto muebles | L36: B2B | N36: 0 | O36: José Bugner | P36: 4653-0722 | S36: 4653-0722 | V36: No encontrado / No tiene | W36: No | X36: No | Y36: Si
A37: C | B37: ACYTRA SAIC S.A. | C37: 30502185787 | D37: Empresa | E37: Av. Lope De Vega | F37: 2341 | G37: Villa Raffo | H37: 1674 | I37: 259309 | J37: Metalúrgica | K37: Fabricación de cerraduras, herrajes y artículos de ferretería N.C.P. | L37: B2C, B2B | M37: Cerraduras, candados | N37: 50 | O37: Pablo Oscar Gonzalez | P37: 11 5582-0350 | Q37: Matías Lacoppola | R37: 11 4043-9530 | S37: 11 4757-0729 | T37: 11 4757-3928 | U37: 11 5582-0360 | V37: https://acytra.com/ | W37: Si | X37: Si | Y37: Si
A38: C | B38: ADHE-MAX S.R.L. | C38: 30708208481 | D38: Empresa | E38: Federico Lacroze | F38: 3636 | G38: Ciudadela | H38: 1702 | I38: 202907 | J38: Química | K38: Fabricación de colas, adhesivos, aprestos y cementos excepto los odontológicos obtenidos de sustancias minerales y vegetales | N38: 3 | S38: 3750-7028 | T38: 4647-3413 | U38: 4647-0900 | V38: No encontrado / No tiene | W38: No | X38: No | Y38: Si
A39: C | B39: ADHEPLAST S.R.L. | C39: 30714362409 | D39: Empresa | E39: Av. Gral. Hornos | F39: 3186 | G39: Caseros | H39: 1678 | I39: 222090 | J39: Plástica | K39: Fabricación de productos plásticos en formas básicas y artículos de plástico N.C.P., excepto muebles | L39: B2B | N39: 1 | S39: 15 5108-4025 | T39: 11 5107-7456 | U39: 11 5434-2330 | V39: https://adheplastonline.com.ar/ | W39: No | X39: No | Y39: Si
A40: C | B40: ADITIVOS PLASTICOS S.R.L. | C40: 30708354011 | D40: Empresa | E40: Juan Larrea | F40: 3144 | G40: Caseros | H40: 1678 | I40: 202908 | J40: Química | K40: Fabricación de productos químicos N.C.P. (Incluye la producción de aceites esenciales, tintas excepto para imprenta, etc.) | N40: 4 | O40: Luis Riccitelli (Gerente) | P40: 15 5335-8743 | Q40: Víctor M. Holub | S40: 11 4751-2148 | T40: 11 4751-6480 | V40: https://aditivosplasticos.com/ | W40: Si | X40: Si | Y40: Si
...

Sheet Mails_Normalizados
A1: EMPRESA | B1: CUIT | C1: RUBRO | D1: EMAIL | E1: TIPO | F1: ESTADO
A2: Razón Social AFIP | D2: leomellimurano@gmail.com | E2: Principal | F2: funcional
A3: Razón Social AFIP | D3: patricianoemireynoso@gmail.com | E3: Principal | F3: funcional
A4: 1989 ESTUDIO A S.R.L. | ALEJANDRO Y MIGUEL ANGEL RIZZI S.H. | B4: =IF(A4="", "", IF(IFERROR(VLOOKUP(A4, 'Base 3F'!$B:$C, 2, FALSE),"")="", "SIN CUIT", VLOOKUP(A4, 'Base 3F'!$B:$C, 2, FALSE))) -> 30709328995 | 30710682816 | C4: =IF(A4="", "", IF(IFERROR(VLOOKUP(A4, 'Base 3F'!$B:$J, 9, FALSE),"")="", "SIN RUBRO", VLOOKUP(A4, 'Base 3F'!$B:$J, 9, FALSE))) -> Papel | D4: angelina@estudioapop.com.ar | E4: Principal | F4: funcional
A5: A D S.A. | B5: =IF(A5="", "", IF(IFERROR(VLOOKUP(A5, 'Base 3F'!$B:$C, 2, FALSE),"")="", "SIN CUIT", VLOOKUP(A5, 'Base 3F'!$B:$C, 2, FALSE))) -> 30710393725 | C5: =IF(A5="", "", IF(IFERROR(VLOOKUP(A5, 'Base 3F'!$B:$J, 9, FALSE),"")="", "SIN RUBRO", VLOOKUP(A5, 'Base 3F'!$B:$J, 9, FALSE))) -> Metalúrgica | D5: lgreco@amasd.com.ar | E5: Principal | F5: funcional
A6: ABELARDO ESTEBAN (VALVULAS ESTEBAN) | B6: =IF(A6="", "", IF(IFERROR(VLOOKUP(A6, 'Base 3F'!$B:$C, 2, FALSE),"")="", "SIN CUIT", VLOOKUP(A6, 'Base 3F'!$B:$C, 2, FALSE))) -> 20105339330 | C6: =IF(A6="", "", IF(IFERROR(VLOOKUP(A6, 'Base 3F'!$B:$J, 9, FALSE),"")="", "SIN RUBRO", VLOOKUP(A6, 'Base 3F'!$B:$J, 9, FALSE))) -> Metalúrgica | D6: liliappardo@yahoo.com.ar | E6: Principal | F6: funcional
A7: ACEROS COFER S.A. | B7: =IF(A7="", "", IF(IFERROR(VLOOKUP(A7, 'Base 3F'!$B:$C, 2, FALSE),"")="", "SIN CUIT", VLOOKUP(A7, 'Base 3F'!$B:$C, 2, FALSE))) -> 30707576444 | C7: =IF(A7="", "", IF(IFERROR(VLOOKUP(A7, 'Base 3F'!$B:$J, 9, FALSE),"")="", "SIN RUBRO", VLOOKUP(A7, 'Base 3F'!$B:$J, 9, FALSE))) -> Metalúrgica | D7: juancluna@aceroscofer.com.ar | E7: Principal | F7: funcional
A8: ACEROS INOXIDABLES ALVEAR S.R.L. | B8: 33715692649 | C8: =IF(A8="", "", IF(IFERROR(VLOOKUP(A8, 'Base 3F'!$B:$J, 9, FALSE),"")="", "SIN RUBRO", VLOOKUP(A8, 'Base 3F'!$B:$J, 9, FALSE))) -> Metalúrgica | D8: info@acerosalvear.com | E8: Principal | F8: rebotado_desconocido
A9: ACEROS INOXIDABLES CASEROS S.R.L. | B9: =IF(A9="", "", IF(IFERROR(VLOOKUP(A9, 'Base 3F'!$B:$C, 2, FALSE),"")="", "SIN CUIT", VLOOKUP(A9, 'Base 3F'!$B:$C, 2, FALSE))) -> 30708161272 | C9: =IF(A9="", "", IF(IFERROR(VLOOKUP(A9, 'Base 3F'!$B:$J, 9, FALSE),"")="", "SIN RUBRO", VLOOKUP(A9, 'Base 3F'!$B:$J, 9, FALSE))) -> Metalúrgica | D9: graciela@inoxicaseros.com.ar | E9: Principal | F9: funcional
A10: ACEROS MB S.A. | B10: =IF(A10="", "", IF(IFERROR(VLOOKUP(A10, 'Base 3F'!$B:$C, 2, FALSE),"")="", "SIN CUIT", VLOOKUP(A10, 'Base 3F'!$B:$C, 2, FALSE))) -> 30584398694 | C10: =IF(A10="", "", IF(IFERROR(VLOOKUP(A10, 'Base 3F'!$B:$J, 9, FALSE),"")="", "SIN RUBRO", VLOOKUP(A10, 'Base 3F'!$B:$J, 9, FALSE))) -> Metalúrgica | D10: vholub@acerosmb.com.ar | E10: Principal | F10: funcional
A11: ACHILLI VIVIANA Y ACHILLI DIEGO SOC. H. (HELADOS LOS AMORES) | B11: =IF(A11="", "", IF(IFERROR(VLOOKUP(A11, 'Base 3F'!$B:$C, 2, FALSE),"")="", "SIN CUIT", VLOOKUP(A11, 'Base 3F'!$B:$C, 2, FALSE))) -> 33708320159 | C11: =IF(A11="", "", IF(IFERROR(VLOOKUP(A11, 'Base 3F'!$B:$J, 9, FALSE),"")="", "SIN RUBRO", VLOOKUP(A11, 'Base 3F'!$B:$J, 9, FALSE))) -> Alimenticia | D11: dachilli@los-amores.com.ar | E11: Principal | F11: funcional
A12: ADITIVOS PLASTICOS S.R.L. | B12: =IF(A12="", "", IF(IFERROR(VLOOKUP(A12, 'Base 3F'!$B:$C, 2, FALSE),"")="", "SIN CUIT", VLOOKUP(A12, 'Base 3F'!$B:$C, 2, FALSE))) -> 30708354011 | C12: =IF(A12="", "", IF(IFERROR(VLOOKUP(A12, 'Base 3F'!$B:$J, 9, FALSE),"")="", "SIN RUBRO", VLOOKUP(A12, 'Base 3F'!$B:$J, 9, FALSE))) -> Química | D12: gerencia@aditivosplasticos.com | E12: Principal | F12: funcional
A13: AFONSO GARCIA GONZALO JAVIER (SOLUPLEX) | B13: =IF(A13="", "", IF(IFERROR(VLOOKUP(A13, 'Base 3F'!$B:$C, 2, FALSE),"")="", "SIN CUIT", VLOOKUP(A13, 'Base 3F'!$B:$C, 2, FALSE))) -> 20262813720 | C13: =IF(A13="", "", IF(IFERROR(VLOOKUP(A13, 'Base 3F'!$B:$J, 9, FALSE),"")="", "SIN RUBRO", VLOOKUP(A13, 'Base 3F'!$B:$J, 9, FALSE))) -> Plástica | D13: gafonso@soluplex.com | E13: Principal | F13: funcional
A14: AG METALURGICA S.A. | B14: =IF(A14="", "", IF(IFERROR(VLOOKUP(A14, 'Base 3F'!$B:$C, 2, FALSE),"")="", "SIN CUIT", VLOOKUP(A14, 'Base 3F'!$B:$C, 2, FALSE))) -> 30712300023 | C14: =IF(A14="", "", IF(IFERROR(VLOOKUP(A14, 'Base 3F'!$B:$J, 9, FALSE),"")="", "SIN RUBRO", VLOOKUP(A14, 'Base 3F'!$B:$J, 9, FALSE))) -> Metalmecánica | D14: eduardo@agmetalurgica.com.ar | E14: Principal | F14: funcional
A15: AIMAN S.A. | B15: =IF(A15="", "", IF(IFERROR(VLOOKUP(A15, 'Base 3F'!$B:$C, 2, FALSE),"")="", "SIN CUIT", VLOOKUP(A15, 'Base 3F'!$B:$C, 2, FALSE))) -> 33646972979 | C15: =IF(A15="", "", IF(IFERROR(VLOOKUP(A15, 'Base 3F'!$B:$J, 9, FALSE),"")="", "SIN RUBRO", VLOOKUP(A15, 'Base 3F'!$B:$J, 9, FALSE))) -> Textil | D15: r-roussilian@aiman-sa.com | E15: Principal | F15: funcional
A16: ALAMBRES INDUSTRIALES TREFILADOS S.R.L. (ACEROS VILLA BOSCH S.A.) | B16: =IF(A16="", "", IF(IFERROR(VLOOKUP(A16, 'Base 3F'!$B:$C, 2, FALSE),"")="", "SIN CUIT", VLOOKUP(A16, 'Base 3F'!$B:$C, 2, FALSE))) -> 30647279909 | C16: =IF(A16="", "", IF(IFERROR(VLOOKUP(A16, 'Base 3F'!$B:$J, 9, FALSE),"")="", "SIN RUBRO", VLOOKUP(A16, 'Base 3F'!$B:$J, 9, FALSE))) -> Metalúrgica | D16: andrescz@acerosbosch.com.ar | E16: Principal | F16: funcional
A17: ALBALONGA S.A. | B17: =IF(A17="", "", IF(IFERROR(VLOOKUP(A17, 'Base 3F'!$B:$C, 2, FALSE),"")="", "SIN CUIT", VLOOKUP(A17, 'Base 3F'!$B:$C, 2, FALSE))) -> 30595286189 | C17: =IF(A17="", "", IF(IFERROR(VLOOKUP(A17, 'Base 3F'!$B:$J, 9, FALSE),"")="", "SIN RUBRO", VLOOKUP(A17, 'Base 3F'!$B:$J, 9, FALSE))) -> Textil | D17: disegno.albalonga@gmail.com | E17: Principal | F17: funcional
A18: ALFONSO SABBATINI E HIJO S.R.L. | B18: =IF(A18="", "", IF(IFERROR(VLOOKUP(A18, 'Base 3F'!$B:$C, 2, FALSE),"")="", "SIN CUIT", VLOOKUP(A18, 'Base 3F'!$B:$C, 2, FALSE))) -> 30709636991 | C18: =IF(A18="", "", IF(IFERROR(VLOOKUP(A18, 'Base 3F'!$B:$J, 9, FALSE),"")="", "SIN RUBRO", VLOOKUP(A18, 'Base 3F'!$B:$J, 9, FALSE))) -> Metalúrgica | D18: alejandro@sabbatini.com.ar | E18: Principal | F18: funcional
A19: ALFONSO SABBATINI E HIJO S.R.L. | B19: =IF(A19="", "", IF(IFERROR(VLOOKUP(A19, 'Base 3F'!$B:$C, 2, FALSE),"")="", "SIN CUIT", VLOOKUP(A19, 'Base 3F'!$B:$C, 2, FALSE))) -> 30709636991 | C19: =IF(A19="", "", IF(IFERROR(VLOOKUP(A19, 'Base 3F'!$B:$J, 9, FALSE),"")="", "SIN RUBRO", VLOOKUP(A19, 'Base 3F'!$B:$J, 9, FALSE))) -> Metalúrgica | D19: eduardo@sabbatini.com.ar | E19: Principal | F19: funcional
A20: ALIMENTOS AGRELE S.R.L. (CRISPPINO) | B20: =IF(A20="", "", IF(IFERROR(VLOOKUP(A20, 'Base 3F'!$B:$C, 2, FALSE),"")="", "SIN CUIT", VLOOKUP(A20, 'Base 3F'!$B:$C, 2, FALSE))) -> 30714502367 | C20: =IF(A20="", "", IF(IFERROR(VLOOKUP(A20, 'Base 3F'!$B:$J, 9, FALSE),"")="", "SIN RUBRO", VLOOKUP(A20, 'Base 3F'!$B:$J, 9, FALSE))) -> Alimenticia | D20: oliver@crisppino.com | E20: Principal | F20: funcional
... A417: BRAGA ALICIA BEATRIZ ( METALURGICA JORGE) | B417: =IF(A417="", "", IF(IFERROR(VLOOKUP(A417, 'Base 3F'!$B:$C, 2, FALSE),"")="", "SIN CUIT", VLOOKUP(A417, 'Base 3F'!$B:$C, 2, FALSE))) -> 27119119907 | C417: =IF(A417="", "", IF(IFERROR(VLOOKUP(A417, 'Base 3F'!$B:$J, 9, FALSE),"")="", "SIN RUBRO", VLOOKUP(A417, 'Base 3F'!$B:$J, 9, FALSE))) -> Metalúrgica | D417: metalurgicajorge@hotmail.com | E417: Secundario | F417: funcional
A418: INDUSTRIA METALURGICA LH S.R.L.- | B418: 33717414379 | C418: =IF(A418="", "", IF(IFERROR(VLOOKUP(A418, 'Base 3F'!$B:$J, 9, FALSE),"")="", "SIN RUBRO", VLOOKUP(A418, 'Base 3F'!$B:$J, 9, FALSE))) -> Metalúrgica | D418: info@metalurgica-lh.com.ar | E418: Secundario | F418: rebotado_desconocido
A419: PANDIANI WALTER HUGO | B419: =IF(A419="", "", IF(IFERROR(VLOOKUP(A419, 'Base 3F'!$B:$C, 2, FALSE),"")="", "SIN CUIT", VLOOKUP(A419, 'Base 3F'!$B:$C, 2, FALSE))) -> 20227214865 | C419: =IF(A419="", "", IF(IFERROR(VLOOKUP(A419, 'Base 3F'!$B:$J, 9, FALSE),"")="", "SIN RUBRO", VLOOKUP(A419, 'Base 3F'!$B:$J, 9, FALSE))) -> Alimenticia | D419: nm.condimentos@gmail.com | E419: Secundario | F419: funcional
A420: ALCOBENDAS SA- | B420: =IF(A420="", "", IF(IFERROR(VLOOKUP(A420, 'Base 3F'!$B:$C, 2, FALSE),"")="", "SIN CUIT", VLOOKUP(A420, 'Base 3F'!$B:$C, 2, FALSE))) -> 30717619753 | C420: =IF(A420="", "", IF(IFERROR(VLOOKUP(A420, 'Base 3F'!$B:$J, 9, FALSE),"")="", "SIN RUBRO", VLOOKUP(A420, 'Base 3F'!$B:$J, 9, FALSE))) -> Alimenticia | D420: madubovsky@gmail.com | E420: Secundario | F420: rebotado_spam
A421: FACCIOPANE S.R.L. | B421: =IF(A421="", "", IF(IFERROR(VLOOKUP(A421, 'Base 3F'!$B:$C, 2, FALSE),"")="", "SIN CUIT", VLOOKUP(A421, 'Base 3F'!$B:$C, 2, FALSE))) -> 30715604635 | C421: =IF(A421="", "", IF(IFERROR(VLOOKUP(A421, 'Base 3F'!$B:$J, 9, FALSE),"")="", "SIN RUBRO", VLOOKUP(A421, 'Base 3F'!$B:$J, 9, FALSE))) -> Alimenticia | D421: ksedani@sgestiongroup.com | E421: Secundario | F421: funcional
A422: IANNELLO, GUSTAVO DOMINGO | B422: =IF(A422="", "", IF(IFERROR(VLOOKUP(A422, 'Base 3F'!$B:$C, 2, FALSE),"")="", "SIN CUIT", VLOOKUP(A422, 'Base 3F'!$B:$C, 2, FALSE))) -> 20308378498 | C422: =IF(A422="", "", IF(IFERROR(VLOOKUP(A422, 'Base 3F'!$B:$J, 9, FALSE),"")="", "SIN RUBRO", VLOOKUP(A422, 'Base 3F'!$B:$J, 9, FALSE))) -> Química | D422: gustavoiannello1984@gmail.com | E422: Secundario | F422: funcional
A423: ALEMAN NORA MIRTA | B423: =IF(A423="", "", IF(IFERROR(VLOOKUP(A423, 'Base 3F'!$B:$C, 2, FALSE),"")="", "SIN CUIT", VLOOKUP(A423, 'Base 3F'!$B:$C, 2, FALSE))) -> 27052789597 | C423: =IF(A423="", "", IF(IFERROR(VLOOKUP(A423, 'Base 3F'!$B:$J, 9, FALSE),"")="", "SIN RUBRO", VLOOKUP(A423, 'Base 3F'!$B:$J, 9, FALSE))) -> Electrónica | D423: va70oviedo@gmail.com | E423: Secundario | F423: funcional
A424: GIANNECCHINI VICTOR MATIAS | B424: =IF(A424="", "", IF(IFERROR(VLOOKUP(A424, 'Base 3F'!$B:$C, 2, FALSE),"")="", "SIN CUIT", VLOOKUP(A424, 'Base 3F'!$B:$C, 2, FALSE))) -> 20359896000 | C424: =IF(A424="", "", IF(IFERROR(VLOOKUP(A424, 'Base 3F'!$B:$J, 9, FALSE),"")="", "SIN RUBRO", VLOOKUP(A424, 'Base 3F'!$B:$J, 9, FALSE))) -> Plástica | D424: matiasgiomecchini@gmail.com | E424: Secundario | F424: funcional
A425: MOGNI JOSE LUIS | B425: =IF(A425="", "", IF(IFERROR(VLOOKUP(A425, 'Base 3F'!$B:$C, 2, FALSE),"")="", "SIN CUIT", VLOOKUP(A425, 'Base 3F'!$B:$C, 2, FALSE))) -> 20176021714 | C425: =IF(A425="", "", IF(IFERROR(VLOOKUP(A425, 'Base 3F'!$B:$J, 9, FALSE),"")="", "SIN RUBRO", VLOOKUP(A425, 'Base 3F'!$B:$J, 9, FALSE))) -> Metalúrgica | D425: JOSELMOGNI@HOTMAIL.COM | E425: Secundario | F425: funcional
A426: CARDOZO JOSE LUIS, ESPLUGAS FRANCISCO JOSE, DIAZ MANUEL, DIAZ FERNANDO SOCIEDAD DE HECHO | B426: =IF(A426="", "", IF(IFERROR(VLOOKUP(A426, 'Base 3F'!$B:$C, 2, FALSE),"")="", "SIN CUIT", VLOOKUP(A426, 'Base 3F'!$B:$C, 2, FALSE))) -> 30712373047 | C426: =IF(A426="", "", IF(IFERROR(VLOOKUP(A426, 'Base 3F'!$B:$J, 9, FALSE),"")="", "SIN RUBRO", VLOOKUP(A426, 'Base 3F'!$B:$J, 9, FALSE))) -> Madera | D426: alriomultilaminados@hotmail.com | E426: Secundario | F426: funcional
A427: DE NUNZIO JUAN PABLO | B427: =IF(A427="", "", IF(IFERROR(VLOOKUP(A427, 'Base 3F'!$B:$C, 2, FALSE),"")="", "SIN CUIT", VLOOKUP(A427, 'Base 3F'!$B:$C, 2, FALSE))) -> 20288571571 | C427: =IF(A427="", "", IF(IFERROR(VLOOKUP(A427, 'Base 3F'!$B:$J, 9, FALSE),"")="", "SIN RUBRO", VLOOKUP(A427, 'Base 3F'!$B:$J, 9, FALSE))) -> Madera | D427: jpablodn@hotmail.com | E427: Secundario | F427: funcional
A428: GROUNDNUT S.R.L. | B428: =IF(A428="", "", IF(IFERROR(VLOOKUP(A428, 'Base 3F'!$B:$C, 2, FALSE),"")="", "SIN CUIT", VLOOKUP(A428, 'Base 3F'!$B:$C, 2, FALSE))) -> 30717389529 | C428: =IF(A428="", "", IF(IFERROR(VLOOKUP(A428, 'Base 3F'!$B:$J, 9, FALSE),"")="", "SIN RUBRO", VLOOKUP(A428, 'Base 3F'!$B:$J, 9, FALSE))) -> Alimenticia | D428: hdimecola@hotmail.com | E428: Secundario | F428: funcional
A429: HERMETICA P.V.C S.R.L | B429: =IF(A429="", "", IF(IFERROR(VLOOKUP(A429, 'Base 3F'!$B:$C, 2, FALSE),"")="", "SIN CUIT", VLOOKUP(A429, 'Base 3F'!$B:$C, 2, FALSE))) -> 33716790369 | C429: =IF(A429="", "", IF(IFERROR(VLOOKUP(A429, 'Base 3F'!$B:$J, 9, FALSE),"")="", "SIN RUBRO", VLOOKUP(A429, 'Base 3F'!$B:$J, 9, FALSE))) -> Metalúrgica | D429: hermeticapvc@gmail.com | E429: Secundario | F429: funcional
A430: NINA LLANQUE VIDAL | B430: =IF(A430="", "", IF(IFERROR(VLOOKUP(A430, 'Base 3F'!$B:$C, 2, FALSE),"")="", "SIN CUIT", VLOOKUP(A430, 'Base 3F'!$B:$C, 2, FALSE))) -> 20940698198 | C430: =IF(A430="", "", IF(IFERROR(VLOOKUP(A430, 'Base 3F'!$B:$J, 9, FALSE),"")="", "SIN RUBRO", VLOOKUP(A430, 'Base 3F'!$B:$J, 9, FALSE))) -> Textil | D430: nina_09ldz@live.com.ar | E430: Secundario | F430: funcional
... A534: PROCESADORA ASAMBLEA S.A- | B534: =IF(A534="", "", IF(IFERROR(VLOOKUP(A534, 'Base 3F'!$B:$C, 2, FALSE),"")="", "SIN CUIT", VLOOKUP(A534, 'Base 3F'!$B:$C, 2, FALSE))) -> 30708070994 | C534: =IF(A534="", "", IF(IFERROR(VLOOKUP(A534, 'Base 3F'!$B:$J, 9, FALSE),"")="", "SIN RUBRO", VLOOKUP(A534, 'Base 3F'!$B:$J, 9, FALSE))) -> Servicios | D534: procesadorajeans@gmail.com | E534: Secundario | F534: funcional
A535: PROFILES ACEROS S.A | B535: =IF(A535="", "", IF(IFERROR(VLOOKUP(A535, 'Base 3F'!$B:$C, 2, FALSE),"")="", "SIN CUIT", VLOOKUP(A535, 'Base 3F'!$B:$C, 2, FALSE))) -> 30714419362 | C535: =IF(A535="", "", IF(IFERROR(VLOOKUP(A535, 'Base 3F'!$B:$J, 9, FALSE),"")="", "SIN RUBRO", VLOOKUP(A535, 'Base 3F'!$B:$J, 9, FALSE))) -> Metalúrgica | D535: profilesaceros@gmail.com | E535: Secundario | F535: funcional | G535: ssss
A536: ACEROS COFER S.A. | B536: =IF(A536="", "", IF(IFERROR(VLOOKUP(A536, 'Base 3F'!$B:$C, 2, FALSE),"")="", "SIN CUIT", VLOOKUP(A536, 'Base 3F'!$B:$C, 2, FALSE))) -> 30707576444 | C536: =IF(A536="", "", IF(IFERROR(VLOOKUP(A536, 'Base 3F'!$B:$J, 9, FALSE),"")="", "SIN RUBRO", VLOOKUP(A536, 'Base 3F'!$B:$J, 9, FALSE))) -> Metalúrgica | D536: aceroscofer@aceroscofer.com.ar | E536: Secundario | F536: funcional
A537: ACEROS MB S.A. | B537: =IF(A537="", "", IF(IFERROR(VLOOKUP(A537, 'Base 3F'!$B:$C, 2, FALSE),"")="", "SIN CUIT", VLOOKUP(A537, 'Base 3F'!$B:$C, 2, FALSE))) -> 30584398694 | C537: =IF(A537="", "", IF(IFERROR(VLOOKUP(A537, 'Base 3F'!$B:$J, 9, FALSE),"")="", "SIN RUBRO", VLOOKUP(A537, 'Base 3F'!$B:$J, 9, FALSE))) -> Metalúrgica | D537: jpmontan@acerosmb.com.ar | E537: Secundario | F537: funcional
A538: ACRILICOS AMENDOLA MARIANI S.R.L. | B538: =IF(A538="", "", IF(IFERROR(VLOOKUP(A538, 'Base 3F'!$B:$C, 2, FALSE),"")="", "SIN CUIT", VLOOKUP(A538, 'Base 3F'!$B:$C, 2, FALSE))) -> 30647516366 | C538: =IF(A538="", "", IF(IFERROR(VLOOKUP(A538, 'Base 3F'!$B:$J, 9, FALSE),"")="", "SIN RUBRO", VLOOKUP(A538, 'Base 3F'!$B:$J, 9, FALSE))) -> Plástica | D538: acrilicosamendolamariani@gmail.com | E538: Secundario | F538: funcional
A539: ACYTRA SAIC S.A. | B539: =IF(A539="", "", IF(IFERROR(VLOOKUP(A539, 'Base 3F'!$B:$C, 2, FALSE),"")="", "SIN CUIT", VLOOKUP(A539, 'Base 3F'!$B:$C, 2, FALSE))) -> 30502185787 | C539: =IF(A539="", "", IF(IFERROR(VLOOKUP(A539, 'Base 3F'!$B:$J, 9, FALSE),"")="", "SIN RUBRO", VLOOKUP(A539, 'Base 3F'!$B:$J, 9, FALSE))) -> Metalúrgica | D539: lacoppma@acytra.com | E539: Secundario | F539: funcional
...

Sheet Mapeo
A1: Rubro | B1: Cantidad | C1: % | E1: Localidad | F1: Cantidad | G1: %
A2: Agropecuaria | B2: =COUNTIF('Base 3F'!J5:J1964, A2) -> 6 | C2: =B2/B$35 -> 0.0033112583 | E2: Caseros | F2: =COUNTIF('Base 3F'!G5:G1964, E2) -> 813 | G2: =F2/F$18 -> 0.40207715
A3: Alimenticia | B3: =COUNTIF('Base 3F'!J5:J1964, A3) -> 113 | C3: =B3/B$35 -> 0.062362031 | E3: Churruca | F3: =COUNTIF('Base 3F'!G6:G1964, E3) -> 2 | G3: =F3/F$18 -> 0.00098911968
A4: Automotor | B4: =COUNTIF('Base 3F'!J5:J1964, A4) -> 14 | C4: =B4/B$35 -> 0.0077262693 | E4: Ciudad Jardín Lomas del Palomar | F4: =COUNTIF('Base 3F'!G7:G1964, E4) -> 16 | G4: =F4/F$18 -> 0.0079129575
A5: Bebidas | B5: =COUNTIF('Base 3F'!J5:J1964, A5) -> 18 | C5: =B5/B$35 -> 0.0099337748 | E5: Ciudadela | F5: =COUNTIF('Base 3F'!G7:G1964, E5) -> 483 | G5: =F5/F$18 -> 0.2388724
A6: Calzado | B6: =COUNTIF('Base 3F'!J5:J1964, A6) -> 33 | C6: =B6/B$35 -> 0.018211921 | E6: El Libertador | F6: =COUNTIF('Base 3F'!G8:G1964, E6) -> 0 | G6: =F6/F$18 -> 0
A7: Caucho | B7: =COUNTIF('Base 3F'!J5:J1964, A7) -> 19 | C7: =B7/B$35 -> 0.010485651 | E7: José Ingenieros | F7: =COUNTIF('Base 3F'!G9:G1964, E7) -> 61 | G7: =F7/F$18 -> 0.03016815
A8: Comercio | B8: =COUNTIF('Base 3F'!J5:J1964, A8) -> 1 | C8: =B8/B$35 -> 0.00055187638 | E8: Loma Hermosa | F8: =COUNTIF('Base 3F'!G10:G1964, E8) -> 235 | G8: =F8/F$18 -> 0.11622156
A9: Construcción | B9: =COUNTIF('Base 3F'!J5:J1964, A9) -> 80 | C9: =B9/B$35 -> 0.04415011 | E9: Martín Coronado | F9: =COUNTIF('Base 3F'!G11:G1964, E9) -> 31 | G9: =F9/F$18 -> 0.015331355
A10: Cosmética | B10: =COUNTIF('Base 3F'!J5:J1964, A10) -> 2 | C10: =B10/B$35 -> 0.0011037528 | E10: Once de Septiembre | F10: =COUNTIF('Base 3F'!G12:G1964, E10) -> 0 | G10: =F10/F$18 -> 0
A11: Cuero | B11: =COUNTIF('Base 3F'!J5:J1964, A11) -> 5 | C11: =B11/B$35 -> 0.0027593819 | E11: Pablo Podestá | F11: =COUNTIF('Base 3F'!G13:G1964, E11) -> 67 | G11: =F11/F$18 -> 0.033135509
A12: Electricidad | B12: =COUNTIF('Base 3F'!J5:J1964, A12) -> 4 | C12: =B12/B$35 -> 0.0022075055 | E12: Remedios de Escalada | F12: =COUNTIF('Base 3F'!G14:G1964, E12) -> 0 | G12: =F12/F$18 -> 0
A13: Electrónica | B13: =COUNTIF('Base 3F'!J5:J1964, A13) -> 67 | C13: =B13/B$35 -> 0.036975717 | E13: Sáenz Peña | F13: =COUNTIF('Base 3F'!G15:G1964, E13) -> 49 | G13: =F13/F$18 -> 0.024233432
A14: Gráfica | B14: =COUNTIF('Base 3F'!J5:J1964, A14) -> 29 | C14: =B14/B$35 -> 0.016004415 | E14: Santos Lugares | F14: =COUNTIF('Base 3F'!G16:G1964, E14) -> 65 | G14: =F14/F$18 -> 0.03214639
A15: Industria | B15: =COUNTIF('Base 3F'!J5:J1964, A15) -> 25 | C15: =B15/B$35 -> 0.013796909 | E15: Villa Bosch | F15: =COUNTIF('Base 3F'!G17:G1964, E15) -> 113 | G15: =F15/F$18 -> 0.055885262
A16: Informática | B16: =COUNTIF('Base 3F'!J5:J1964, A16) -> 4 | C16: =B16/B$35 -> 0.0022075055 | E16: Villa Raffo | F16: =COUNTIF('Base 3F'!G18:G1964, E16) -> 20 | G16: =F16/F$18 -> 0.0098911968
A17: Logística | B17: =COUNTIF('Base 3F'!J5:J1964, A17) -> 1 | C17: =B17/B$35 -> 0.00055187638 | E17: Fuera de 3F | F17: 67 | G17: =F17/F$18 -> 0.033135509
A18: Madera | B18: =COUNTIF('Base 3F'!J5:J1964, A18) -> 114 | C18: =B18/B$35 -> 0.062913907 | E18: TOTALES | F18: =SUM(F2:F17) -> 2022 | G18: =SUM(G2:G17) -> 1
A19: Manufactura | B19: =COUNTIF('Base 3F'!J5:J1964, A19) -> 16 | C19: =B19/B$35 -> 0.0088300221
A20: Metalmecánica | B20: =COUNTIF('Base 3F'!J5:J1964, A20) -> 80 | C20: =B20/B$35 -> 0.04415011
A21: Metalúrgica | B21: =COUNTIF('Base 3F'!J5:J1964, A21) -> 637 | C21: =B21/B$35 -> 0.35154525
A22: Minería | B22: =COUNTIF('Base 3F'!J5:J1964, A22) -> 1 | C22: =B22/B$35 -> 0.00055187638
A23: Olivicola | B23: =COUNTIF('Base 3F'!J5:J1964, A23) -> 1 | C23: =B23/B$35 -> 0.00055187638
A24: Orfebrería | B24: =COUNTIF('Base 3F'!J5:J1964, A24) -> 2 | C24: =B24/B$35 -> 0.0011037528
A25: Papel | B25: =COUNTIF('Base 3F'!J5:J1964, A25) -> 47 | C25: =B25/B$35 -> 0.02593819
A26: Petróleo | B26: =COUNTIF('Base 3F'!J5:J1964, A26) -> 1 | C26: =B26/B$35 -> 0.00055187638
A27: Piedra | B27: =COUNTIF('Base 3F'!J5:J1964, A27) -> 3 | C27: =B27/B$35 -> 0.0016556291
A28: Plástico | B28: =COUNTIF('Base 3F'!J5:J1964, A28) -> 0 | C28: =B28/B$35 -> 0
A29: Publicidad | B29: =COUNTIF('Base 3F'!J5:J1964, A29) -> 1 | C29: =B29/B$35 -> 0.00055187638
A30: Servicios | B30: =COUNTIF('Base 3F'!J5:J1964, A30) -> 241 | C30: =B30/B$35 -> 0.13300221
A31: Química | B31: =COUNTIF('Base 3F'!J5:J1964, A31) -> 90 | C31: =B31/B$35 -> 0.049668874
A32: Textil | B32: =COUNTIF('Base 3F'!J5:J1964, A32) -> 146 | C32: =B32/B$35 -> 0.080573951
A33: Vidrio | B33: =COUNTIF('Base 3F'!J5:J1964, A33) -> 9 | C33: =B33/B$35 -> 0.0049668874
A34: Otros | B34: =COUNTIF('Base 3F'!J5:J1964, "=-") -> 2 | C34: =B34/B$35 -> 0.0011037528
A35: TOTALES | B35: =SUM(B2:B34) -> 1812 | C35: =SUM(C2:C34) -> 1

Sheet Contacto 1 y 2 (a eliminar)
A1: CONTACTO 1 | B1: 746 mails
A3: angelina@estudioapop.com.ar
A4: lgreco@amasd.com.ar
A5: liliappardo@yahoo.com.ar
A6: juancluna@aceroscofer.com.ar
A7: info@acerosalvear.com
A8: graciela@inoxicaseros.com.ar
A9: vholub@acerosmb.com.ar
A10: holubvictor@gmail.com
A11: dachilli@los-amores.com.ar
A12: gerencia@aditivosplasticos.com
A13: gafonso@soluplex.com
A14: eduardo@agmetalurgica.com.ar
... A757: gmartin@valke.com.ar
A758: arredamentosbosch@hotmail.com | B758: Nuevos contacto 1
A759: info@mis-plast.com.ar
A760: fabfit@hotmail.com
A761: malmebsrl@outlook.com
A762: admmieleselchaltensrl@gmail.com
A763: fernando@wiremac.com.ar
A764: procesadorajeans@gmail.com
A765: profilesaceros@gmail.com
A766: mgraviotto@burkool.com.ar
A767: info@maferbul.com.ar
A768: martingabrielluna@yahoo.com
A769: corradiniremaches@gmail.com
A770: hcorraremaches@gmail.com
A771: corradiniricardov@gmail.com
B773: Contacto 2

Sheet Mails A(a eliminar)
A1: mails A | C1: 522 mails
A2: angelina@estudioapop.com.ar
A3: lgreco@amasd.com.ar
A4: liliappardo@yahoo.com.ar
A5: juancluna@aceroscofer.com.ar
A6: info@acerosalvear.com
A7: graciela@inoxicaseros.com.ar
A8: vholub@acerosmb.com.ar
A9: holubvictor@gmail.com
A10: gerencia@aditivosplasticos.com
A11: gafonso@soluplex.com
A12: eduardo@agmetalurgica.com.ar
A13: r-roussilian@aiman-sa.com
... A531: gasamed@hotmail.com
